<?xml version="1.0" encoding="utf-8"?>
<robot name="robot_4axes">

  <material name="blue"><color rgba="0.0 0.0 0.8 1.0"/></material>
  <material name="white"><color rgba="1.0 1.0 1.0 1.0"/></material>
  <material name="grey"><color rgba="0.3 0.3 0.3 1.0"/></material>
  <material name="red"><color rgba="0.8 0.0 0.0 1.0"/></material>





  <link name="base_link">
    <visual>
      <geometry>
      
    
      </geometry>
        <origin xyz="0 0 0" rpy="0 0 0"/>
      <material name="grey"/>
    </visual>
  </link>

  <joint name="waist_joint" type="revolute">
    <parent link="base_link"/>
    <child link="link_1"/>
    <origin xyz="0 0 0.025" rpy="0 0 0"/>
    <axis xyz="0 0 1"/>
    <limit lower="-3.1416" upper="3.1416" effort="150.0" velocity="1.0"/>
  </joint>

  <link name="link_1">
    <visual>
      <origin xyz="0 0 0.05"/>
      <geometry>
      <mesh filename="../meshes/ok.stl" scale="0.001 0.001 0.001"/>
      </geometry>
      <material name="blue"/>
    </visual>
  </link>




</robot>
