<robot name="robot_arm">

  <!-- Base link -->
  <link name="base"/>

  <!-- Links -->
  <link name="link1"/>
  <link name="link2"/>
  <link name="link3"/>
  <link name="link4"/>
  <link name="link5"/>

  <!-- Base joint -->
  <joint name="base_joint" type="revolute">
    <parent link="base"/>
    <child link="link1"/>
    <origin xyz="0 0 0.1" rpy="0 0 0"/>
    <axis xyz="0 0 1"/>
    <limit lower="0" upper="3.14159" effort="1" velocity="1"/>
  </joint>

  <!-- A1 joint -->
  <joint name="A1_joint" type="revolute">
    <parent link="link1"/>
    <child link="link2"/>
    <origin xyz="0 0 0.2" rpy="0 0 0"/>
    <axis xyz="0 1 0"/>
    <limit lower="0" upper="3.14159" effort="1" velocity="1"/>
  </joint>

  <!-- A2 joint -->
  <joint name="A2_joint" type="revolute">
    <parent link="link2"/>
    <child link="link3"/>
    <origin xyz="0 0 0.2" rpy="0 0 0"/>
    <axis xyz="0 1 0"/>
    <limit lower="0" upper="3.14159" effort="1" velocity="1"/>
  </joint>

  <!-- A3 joint -->
  <joint name="A3_joint" type="revolute">
    <parent link="link3"/>
    <child link="link4"/>
    <origin xyz="0 0 0.2" rpy="0 0 0"/>
    <axis xyz="0 1 0"/>
    <limit lower="0" upper="3.14159" effort="1" velocity="1"/>
  </joint>

  <!-- A4 joint -->
  <joint name="A4_joint" type="revolute">
    <parent link="link4"/>
    <child link="link5"/>
    <origin xyz="0 0 0.2" rpy="0 0 0"/>
    <axis xyz="0 1 0"/>
    <limit lower="0" upper="3.14159" effort="1" velocity="1"/>
  </joint>

</robot>